<sdf version='1.7'>
  <world name='default'>
    <light name='sun' type='directional'>
      <cast_shadows>1</cast_shadows>
      <pose>0 0 10 0 -0 0</pose>
      <diffuse>0.8 0.8 0.8 1</diffuse>
      <specular>0.2 0.2 0.2 1</specular>
      <attenuation>
        <range>1000</range>
        <constant>0.9</constant>
        <linear>0.01</linear>
        <quadratic>0.001</quadratic>
      </attenuation>
      <direction>-0.5 0.1 -0.9</direction>
      <spot>
        <inner_angle>0</inner_angle>
        <outer_angle>0</outer_angle>
        <falloff>0</falloff>
      </spot>
    </light>
    <model name='ground_plane'>
      <static>1</static>
      <link name='link'>
        <collision name='collision'>
          <geometry>
            <plane>
              <normal>0 0 1</normal>
              <size>100 100</size>
            </plane>
          </geometry>
          <surface>
            <friction>
              <ode>
                <mu>100</mu>
                <mu2>50</mu2>
              </ode>
              <torsional>
                <ode/>
              </torsional>
            </friction>
            <contact>
              <ode/>
            </contact>
            <bounce/>
          </surface>
          <max_contacts>10</max_contacts>
        </collision>
        <visual name='visual'>
          <cast_shadows>0</cast_shadows>
          <geometry>
            <plane>
              <normal>0 0 1</normal>
              <size>100 100</size>
            </plane>
          </geometry>
          <material>
            <script>
              <uri>file://media/materials/scripts/gazebo.material</uri>
              <name>Gazebo/Grey</name>
            </script>
          </material>
        </visual>
        <self_collide>0</self_collide>
        <enable_wind>0</enable_wind>
        <kinematic>0</kinematic>
      </link>
    </model>
    <gravity>0 0 -9.8</gravity>
    <magnetic_field>6e-06 2.3e-05 -4.2e-05</magnetic_field>
    <atmosphere type='adiabatic'/>
    <physics type='ode'>
      <max_step_size>0.001</max_step_size>
      <real_time_factor>1</real_time_factor>
      <real_time_update_rate>1000</real_time_update_rate>
    </physics>
    <scene>
      <ambient>0.4 0.4 0.4 1</ambient>
      <background>0.7 0.7 0.7 1</background>
      <shadows>1</shadows>
    </scene>
    <audio>
      <device>default</device>
    </audio>
    <wind/>
    <spherical_coordinates>
      <surface_model>EARTH_WGS84</surface_model>
      <latitude_deg>0</latitude_deg>
      <longitude_deg>0</longitude_deg>
      <elevation>0</elevation>
      <heading_deg>0</heading_deg>
    </spherical_coordinates>
    <model name='ur'>
      <joint name='base_joint' type='fixed'>
        <pose relative_to='__model__'>0 0 0 0 -0 0</pose>
        <parent>world</parent>
        <child>base_link</child>
      </joint>
      <link name='base_link'>
        <pose relative_to='base_joint'>0 0 0 0 -0 0</pose>
        <inertial>
          <pose>0.035144 0.017375 0.069317 0 -0 0</pose>
          <mass>2.072</mass>
          <inertia>
            <ixx>0.296991</ixx>
            <ixy>-0.035144</ixy>
            <ixz>-0.140193</ixz>
            <iyy>0.350696</iyy>
            <iyz>-0.0693173</iyz>
            <izz>0.094131</izz>
          </inertia>
        </inertial>
        <collision name='base_link_inertia_collision'>
          <pose>0 0 0 0 -0 0</pose>
          <geometry>
            <mesh>
              <scale>1 1 1</scale>
              <uri>file:///home/oj/ur3_ws/install/ur_description/share/ur_description/meshes/ur3e/collision/base.stl</uri>
            </mesh>
          </geometry>
          <max_contacts>10</max_contacts>
          <surface>
            <contact>
              <ode/>
            </contact>
            <bounce/>
            <friction>
              <torsional>
                <ode/>
              </torsional>
              <ode/>
            </friction>
          </surface>
        </collision>
        <collision name='base_link_fixed_joint_lump__d435_link_collision_1'>
          <pose>1.01137 0.5 1.9948 3.14159 1.14159 3.14159</pose>
          <geometry>
            <box>
              <size>0.02505 0.09 0.025</size>
            </box>
          </geometry>
          <surface>
            <contact>
              <ode>
                <kp>1e+13</kp>
                <kd>1</kd>
              </ode>
            </contact>
            <friction>
              <ode>
                <mu2>1</mu2>
                <fdir1>0 0 0</fdir1>
              </ode>
              <torsional>
                <ode/>
              </torsional>
            </friction>
            <bounce/>
          </surface>
          <max_contacts>10</max_contacts>
        </collision>
        <visual name='base_link_inertia_visual'>
          <pose>0 0 0 0 -0 0</pose>
          <geometry>
            <mesh>
              <scale>1 1 1</scale>
              <uri>file:///home/oj/ur3_ws/install/ur_description/share/ur_description/meshes/ur3e/visual/base.dae</uri>
            </mesh>
          </geometry>
        </visual>
        <visual name='base_link_fixed_joint_lump__d435_link_visual_1'>
          <pose>1.00517 0.5 1.98125 -2.71239 -0 1.5708</pose>
          <geometry>
            <mesh>
              <scale>1 1 1</scale>
              <uri>file:///home/oj/ur3_ws/install/realsense_ros_gazebo/share/realsense_ros_gazebo/meshes/realsense_d435.stl</uri>
            </mesh>
          </geometry>
        </visual>
        <self_collide>0</self_collide>
        <enable_wind>0</enable_wind>
        <kinematic>0</kinematic>
        <gravity>1</gravity>
        <sensor name='d435_color' type='camera'>
          <camera name='d435'>
            <horizontal_fov>1.21126</horizontal_fov>
            <image>
              <width>640</width>
              <height>480</height>
              <format>RGB_INT8</format>
            </image>
            <clip>
              <near>0.1</near>
              <far>100</far>
            </clip>
            <noise>
              <type>gaussian</type>
              <mean>0</mean>
              <stddev>0.007</stddev>
            </noise>
          </camera>
          <always_on>1</always_on>
          <update_rate>30</update_rate>
          <visualize>1</visualize>
          <pose>1.01137 0.5175 1.9948 3.14159 1.14159 3.14159</pose>
        </sensor>
        <sensor name='d435_ired1' type='camera'>
          <camera name='d435'>
            <horizontal_fov>1.48702</horizontal_fov>
            <image>
              <width>1280</width>
              <height>720</height>
              <format>L_INT8</format>
            </image>
            <clip>
              <near>0.1</near>
              <far>100</far>
            </clip>
            <noise>
              <type>gaussian</type>
              <mean>0</mean>
              <stddev>0.05</stddev>
            </noise>
          </camera>
          <always_on>1</always_on>
          <update_rate>90</update_rate>
          <visualize>0</visualize>
          <pose>1.01137 0.5175 1.9948 3.14159 1.14159 3.14159</pose>
        </sensor>
        <sensor name='d435_ired2' type='camera'>
          <camera name='d435'>
            <horizontal_fov>1.48702</horizontal_fov>
            <image>
              <width>1280</width>
              <height>720</height>
              <format>L_INT8</format>
            </image>
            <clip>
              <near>0.1</near>
              <far>100</far>
            </clip>
            <noise>
              <type>gaussian</type>
              <mean>0</mean>
              <stddev>0.05</stddev>
            </noise>
          </camera>
          <always_on>1</always_on>
          <update_rate>90</update_rate>
          <visualize>0</visualize>
          <pose>1.01137 0.5175 1.9948 3.14159 1.14159 3.14159</pose>
        </sensor>
        <sensor name='d435_depth' type='depth'>
          <camera name='d435'>
            <horizontal_fov>1.48702</horizontal_fov>
            <image>
              <width>1280</width>
              <height>720</height>
            </image>
            <clip>
              <near>0.1</near>
              <far>100</far>
            </clip>
            <noise>
              <type>gaussian</type>
              <mean>0</mean>
              <stddev>0.1</stddev>
            </noise>
          </camera>
          <always_on>1</always_on>
          <update_rate>90</update_rate>
          <visualize>0</visualize>
          <pose>1.01137 0.5175 1.9948 3.14159 1.14159 3.14159</pose>
        </sensor>
      </link>
      <joint name='shoulder_pan_joint' type='revolute'>
        <pose relative_to='base_link'>0 0 0.15185 0 -0 3.14159</pose>
        <parent>base_link</parent>
        <child>shoulder_link</child>
        <axis>
          <xyz>0 0 1</xyz>
          <limit>
            <lower>-6.28319</lower>
            <upper>6.28319</upper>
            <effort>56</effort>
            <velocity>3.14159</velocity>
          </limit>
          <dynamics>
            <damping>0</damping>
            <friction>0</friction>
            <spring_reference>0</spring_reference>
            <spring_stiffness>0</spring_stiffness>
          </dynamics>
        </axis>
      </joint>
      <link name='shoulder_link'>
        <pose relative_to='shoulder_pan_joint'>0 0 0 0 -0 0</pose>
        <inertial>
          <pose>0 0 0 0 -0 0</pose>
          <mass>2</mass>
          <inertia>
            <ixx>0.00809316</ixx>
            <ixy>0</ixy>
            <ixz>0</ixz>
            <iyy>0.00809316</iyy>
            <iyz>0</iyz>
            <izz>0.005625</izz>
          </inertia>
        </inertial>
        <collision name='shoulder_link_collision'>
          <pose>0 0 0 0 -0 3.14159</pose>
          <geometry>
            <mesh>
              <scale>1 1 1</scale>
              <uri>file:///home/oj/ur3_ws/install/ur_description/share/ur_description/meshes/ur3e/collision/shoulder.stl</uri>
            </mesh>
          </geometry>
          <max_contacts>10</max_contacts>
          <surface>
            <contact>
              <ode/>
            </contact>
            <bounce/>
            <friction>
              <torsional>
                <ode/>
              </torsional>
              <ode/>
            </friction>
          </surface>
        </collision>
        <visual name='shoulder_link_visual'>
          <pose>0 0 0 0 -0 3.14159</pose>
          <geometry>
            <mesh>
              <scale>1 1 1</scale>
              <uri>file:///home/oj/ur3_ws/install/ur_description/share/ur_description/meshes/ur3e/visual/shoulder.dae</uri>
            </mesh>
          </geometry>
        </visual>
        <self_collide>0</self_collide>
        <enable_wind>0</enable_wind>
        <kinematic>0</kinematic>
      </link>
      <joint name='shoulder_lift_joint' type='revolute'>
        <pose relative_to='shoulder_link'>0 0 0 1.5708 -0 0</pose>
        <parent>shoulder_link</parent>
        <child>upper_arm_link</child>
        <axis>
          <xyz>0 0 1</xyz>
          <limit>
            <lower>-6.28319</lower>
            <upper>6.28319</upper>
            <effort>56</effort>
            <velocity>3.14159</velocity>
          </limit>
          <dynamics>
            <damping>0</damping>
            <friction>0</friction>
            <spring_reference>0</spring_reference>
            <spring_stiffness>0</spring_stiffness>
          </dynamics>
        </axis>
      </joint>
      <link name='upper_arm_link'>
        <pose relative_to='shoulder_lift_joint'>0 0 0 0 -0 0</pose>
        <inertial>
          <pose>-0.121825 0 0.12 3.14159 1.57079 3.14159</pose>
          <mass>3.42</mass>
          <inertia>
            <ixx>0.0217285</ixx>
            <ixy>0</ixy>
            <ixz>0</ixz>
            <iyy>0.0217285</iyy>
            <iyz>0</iyz>
            <izz>0.00961875</izz>
          </inertia>
        </inertial>
        <collision name='upper_arm_link_collision'>
          <pose>0 0 0.12 1.5708 0 -1.5708</pose>
          <geometry>
            <mesh>
              <scale>1 1 1</scale>
              <uri>file:///home/oj/ur3_ws/install/ur_description/share/ur_description/meshes/ur3e/collision/upperarm.stl</uri>
            </mesh>
          </geometry>
          <max_contacts>10</max_contacts>
          <surface>
            <contact>
              <ode/>
            </contact>
            <bounce/>
            <friction>
              <torsional>
                <ode/>
              </torsional>
              <ode/>
            </friction>
          </surface>
        </collision>
        <visual name='upper_arm_link_visual'>
          <pose>0 0 0.12 1.5708 0 -1.5708</pose>
          <geometry>
            <mesh>
              <scale>1 1 1</scale>
              <uri>file:///home/oj/ur3_ws/install/ur_description/share/ur_description/meshes/ur3e/visual/upperarm.dae</uri>
            </mesh>
          </geometry>
        </visual>
        <self_collide>0</self_collide>
        <enable_wind>0</enable_wind>
        <kinematic>0</kinematic>
      </link>
      <joint name='elbow_joint' type='revolute'>
        <pose relative_to='upper_arm_link'>-0.24355 0 0 0 -0 0</pose>
        <parent>upper_arm_link</parent>
        <child>forearm_link</child>
        <axis>
          <xyz>0 0 1</xyz>
          <limit>
            <lower>-3.14159</lower>
            <upper>3.14159</upper>
            <effort>28</effort>
            <velocity>3.14159</velocity>
          </limit>
          <dynamics>
            <damping>0</damping>
            <friction>0</friction>
            <spring_reference>0</spring_reference>
            <spring_stiffness>0</spring_stiffness>
          </dynamics>
        </axis>
      </joint>
      <link name='forearm_link'>
        <pose relative_to='elbow_joint'>0 0 0 0 -0 0</pose>
        <inertial>
          <pose>-0.1066 0 0.027 3.14159 1.57079 3.14159</pose>
          <mass>1.26</mass>
          <inertia>
            <ixx>0.00654457</ixx>
            <ixy>0</ixy>
            <ixz>0</ixz>
            <iyy>0.00654457</iyy>
            <iyz>0</iyz>
            <izz>0.00354375</izz>
          </inertia>
        </inertial>
        <collision name='forearm_link_collision'>
          <pose>0 0 0.027 1.5708 0 -1.5708</pose>
          <geometry>
            <mesh>
              <scale>1 1 1</scale>
              <uri>file:///home/oj/ur3_ws/install/ur_description/share/ur_description/meshes/ur3e/collision/forearm.stl</uri>
            </mesh>
          </geometry>
          <max_contacts>10</max_contacts>
          <surface>
            <contact>
              <ode/>
            </contact>
            <bounce/>
            <friction>
              <torsional>
                <ode/>
              </torsional>
              <ode/>
            </friction>
          </surface>
        </collision>
        <visual name='forearm_link_visual'>
          <pose>0 0 0.027 1.5708 0 -1.5708</pose>
          <geometry>
            <mesh>
              <scale>1 1 1</scale>
              <uri>file:///home/oj/ur3_ws/install/ur_description/share/ur_description/meshes/ur3e/visual/forearm.dae</uri>
            </mesh>
          </geometry>
        </visual>
        <self_collide>0</self_collide>
        <enable_wind>0</enable_wind>
        <kinematic>0</kinematic>
      </link>
      <joint name='wrist_1_joint' type='revolute'>
        <pose relative_to='forearm_link'>-0.2132 0 0.13105 0 -0 0</pose>
        <parent>forearm_link</parent>
        <child>wrist_1_link</child>
        <axis>
          <xyz>0 0 1</xyz>
          <limit>
            <lower>-6.28319</lower>
            <upper>6.28319</upper>
            <effort>12</effort>
            <velocity>6.28319</velocity>
          </limit>
          <dynamics>
            <damping>0</damping>
            <friction>0</friction>
            <spring_reference>0</spring_reference>
            <spring_stiffness>0</spring_stiffness>
          </dynamics>
        </axis>
      </joint>
      <link name='wrist_1_link'>
        <pose relative_to='wrist_1_joint'>0 0 0 0 -0 0</pose>
        <inertial>
          <pose>0 0 0 0 -0 0</pose>
          <mass>0.8</mass>
          <inertia>
            <ixx>0.002085</ixx>
            <ixy>0</ixy>
            <ixz>0</ixz>
            <iyy>0.002085</iyy>
            <iyz>0</iyz>
            <izz>0.00225</izz>
          </inertia>
        </inertial>
        <collision name='wrist_1_link_collision'>
          <pose>0 0 -0.104 1.5708 -0 0</pose>
          <geometry>
            <mesh>
              <scale>1 1 1</scale>
              <uri>file:///home/oj/ur3_ws/install/ur_description/share/ur_description/meshes/ur3e/collision/wrist1.stl</uri>
            </mesh>
          </geometry>
          <max_contacts>10</max_contacts>
          <surface>
            <contact>
              <ode/>
            </contact>
            <bounce/>
            <friction>
              <torsional>
                <ode/>
              </torsional>
              <ode/>
            </friction>
          </surface>
        </collision>
        <visual name='wrist_1_link_visual'>
          <pose>0 0 -0.104 1.5708 -0 0</pose>
          <geometry>
            <mesh>
              <scale>1 1 1</scale>
              <uri>file:///home/oj/ur3_ws/install/ur_description/share/ur_description/meshes/ur3e/visual/wrist1.dae</uri>
            </mesh>
          </geometry>
        </visual>
        <self_collide>0</self_collide>
        <enable_wind>0</enable_wind>
        <kinematic>0</kinematic>
      </link>
      <joint name='wrist_2_joint' type='revolute'>
        <pose relative_to='wrist_1_link'>0 -0.08535 -0 1.5708 -0 0</pose>
        <parent>wrist_1_link</parent>
        <child>wrist_2_link</child>
        <axis>
          <xyz>0 0 1</xyz>
          <limit>
            <lower>-6.28319</lower>
            <upper>6.28319</upper>
            <effort>12</effort>
            <velocity>6.28319</velocity>
          </limit>
          <dynamics>
            <damping>0</damping>
            <friction>0</friction>
            <spring_reference>0</spring_reference>
            <spring_stiffness>0</spring_stiffness>
          </dynamics>
        </axis>
      </joint>
      <link name='wrist_2_link'>
        <pose relative_to='wrist_2_joint'>0 0 0 0 -0 0</pose>
        <inertial>
          <pose>0 0 0 0 -0 0</pose>
          <mass>0.8</mass>
          <inertia>
            <ixx>0.002085</ixx>
            <ixy>0</ixy>
            <ixz>0</ixz>
            <iyy>0.002085</iyy>
            <iyz>0</iyz>
            <izz>0.00225</izz>
          </inertia>
        </inertial>
        <collision name='wrist_2_link_collision'>
          <pose>0 0 -0.08535 0 -0 0</pose>
          <geometry>
            <mesh>
              <scale>1 1 1</scale>
              <uri>file:///home/oj/ur3_ws/install/ur_description/share/ur_description/meshes/ur3e/collision/wrist2.stl</uri>
            </mesh>
          </geometry>
          <max_contacts>10</max_contacts>
          <surface>
            <contact>
              <ode/>
            </contact>
            <bounce/>
            <friction>
              <torsional>
                <ode/>
              </torsional>
              <ode/>
            </friction>
          </surface>
        </collision>
        <visual name='wrist_2_link_visual'>
          <pose>0 0 -0.08535 0 -0 0</pose>
          <geometry>
            <mesh>
              <scale>1 1 1</scale>
              <uri>file:///home/oj/ur3_ws/install/ur_description/share/ur_description/meshes/ur3e/visual/wrist2.dae</uri>
            </mesh>
          </geometry>
        </visual>
        <self_collide>0</self_collide>
        <enable_wind>0</enable_wind>
        <kinematic>0</kinematic>
      </link>
      <joint name='wrist_3_joint' type='revolute'>
        <pose relative_to='wrist_2_link'>0 0.0921 -0 -1.5708 0 0</pose>
        <parent>wrist_2_link</parent>
        <child>wrist_3_link</child>
        <axis>
          <xyz>0 0 1</xyz>
          <limit>
            <lower>-6.28319</lower>
            <upper>6.28319</upper>
            <effort>12</effort>
            <velocity>6.28319</velocity>
          </limit>
          <dynamics>
            <damping>0</damping>
            <friction>0</friction>
            <spring_reference>0</spring_reference>
            <spring_stiffness>0</spring_stiffness>
          </dynamics>
        </axis>
      </joint>
      <link name='wrist_3_link'>
        <pose relative_to='wrist_3_joint'>0 0 0 0 -0 0</pose>
        <inertial>
          <pose>0 0 -0.02 0 -0 0</pose>
          <mass>0.35</mass>
          <inertia>
            <ixx>0.000136267</ixx>
            <ixy>0</ixy>
            <ixz>0</ixz>
            <iyy>0.000136267</iyy>
            <iyz>0</iyz>
            <izz>0.0001792</izz>
          </inertia>
        </inertial>
        <collision name='wrist_3_link_collision'>
          <pose>0 0 -0.0921 1.5708 -0 0</pose>
          <geometry>
            <mesh>
              <scale>1 1 1</scale>
              <uri>file:///home/oj/ur3_ws/install/ur_description/share/ur_description/meshes/ur3e/collision/wrist3.stl</uri>
            </mesh>
          </geometry>
          <max_contacts>10</max_contacts>
          <surface>
            <contact>
              <ode/>
            </contact>
            <bounce/>
            <friction>
              <torsional>
                <ode/>
              </torsional>
              <ode/>
            </friction>
          </surface>
        </collision>
        <visual name='wrist_3_link_visual'>
          <pose>0 0 -0.0921 1.5708 -0 0</pose>
          <geometry>
            <mesh>
              <scale>1 1 1</scale>
              <uri>file:///home/oj/ur3_ws/install/ur_description/share/ur_description/meshes/ur3e/visual/wrist3.dae</uri>
            </mesh>
          </geometry>
        </visual>
        <self_collide>0</self_collide>
        <enable_wind>0</enable_wind>
        <kinematic>0</kinematic>
      </link>
      <plugin name='d435' filename='librealsense_gazebo_plugin.so'>
        <prefix>d435_</prefix>
        <depthUpdateRate>10</depthUpdateRate>
        <colorUpdateRate>10</colorUpdateRate>
        <infraredUpdateRate>10</infraredUpdateRate>
        <depthTopicName>depth/image_raw</depthTopicName>
        <depthCameraInfoTopicName>depth/camera_info</depthCameraInfoTopicName>
        <colorTopicName>color/image_raw</colorTopicName>
        <colorCameraInfoTopicName>color/camera_info</colorCameraInfoTopicName>
        <infrared1TopicName>infra1/image_raw</infrared1TopicName>
        <infrared1CameraInfoTopicName>infra1/camera_info</infrared1CameraInfoTopicName>
        <infrared2TopicName>infra2/image_raw</infrared2TopicName>
        <infrared2CameraInfoTopicName>infra2/camera_info</infrared2CameraInfoTopicName>
        <colorOpticalframeName>d435_color_optical_frame</colorOpticalframeName>
        <depthOpticalframeName>d435_depth_optical_frame</depthOpticalframeName>
        <infrared1OpticalframeName>d435_infrared1_optical_frame</infrared1OpticalframeName>
        <infrared2OpticalframeName>d435_infrared2_optical_frame</infrared2OpticalframeName>
        <rangeMinDepth>0.2</rangeMinDepth>
        <rangeMaxDepth>10.0</rangeMaxDepth>
        <pointCloud>0</pointCloud>
        <pointCloudTopicName>depth/color/points</pointCloudTopicName>
        <pointCloudCutoff>0.25</pointCloudCutoff>
        <pointCloudCutoffMax>9.0</pointCloudCutoffMax>
      </plugin>
      <static>0</static>
      <plugin name='gazebo_ros2_control' filename='libgazebo_ros2_control.so'>
        <parameters>/home/oj/ur3_ws/install/ur_simulation_gazebo/share/ur_simulation_gazebo/config/ur_controllers.yaml</parameters>
      </plugin>
      <pose>0 0 0 0 -0 0</pose>
    </model>
    <model name='wood_cube_10cm'>
      <link name='link'>
        <pose>0 0 0.05 0 -0 0</pose>
        <inertial>
          <mass>0.5167</mass>
          <inertia>
            <ixx>0.000861167</ixx>
            <ixy>0</ixy>
            <ixz>0</ixz>
            <iyy>0.000861167</iyy>
            <iyz>0</iyz>
            <izz>0.000861167</izz>
          </inertia>
          <pose>0 0 0 0 -0 0</pose>
        </inertial>
        <collision name='collision'>
          <geometry>
            <box>
              <size>0.1 0.1 0.1</size>
            </box>
          </geometry>
          <surface>
            <contact>
              <poissons_ratio>0.347</poissons_ratio>
              <elastic_modulus>8.8e+09</elastic_modulus>
              <ode>
                <kp>100000</kp>
                <kd>100</kd>
                <max_vel>100</max_vel>
                <min_depth>0.001</min_depth>
              </ode>
            </contact>
            <friction>
              <torsional>
                <coefficient>1</coefficient>
                <use_patch_radius>0</use_patch_radius>
                <surface_radius>0.01</surface_radius>
                <ode/>
              </torsional>
              <ode/>
            </friction>
            <bounce/>
          </surface>
          <max_contacts>10</max_contacts>
        </collision>
        <visual name='visual'>
          <geometry>
            <box>
              <size>0.1 0.1 0.1</size>
            </box>
          </geometry>
          <material>
            <script>
              <uri>file://media/materials/scripts/gazebo.material</uri>
              <name>Gazebo/Wood</name>
            </script>
          </material>
        </visual>
        <self_collide>0</self_collide>
        <enable_wind>0</enable_wind>
        <kinematic>0</kinematic>
      </link>
      <pose>0.190577 0.162346 0 0 -0 0</pose>
    </model>
    <state world_name='default'>
      <sim_time>205 979000000</sim_time>
      <real_time>209 191151090</real_time>
      <wall_time>1720430556 752862854</wall_time>
      <iterations>205979</iterations>
      <model name='ground_plane'>
        <pose>0 0 0 0 -0 0</pose>
        <scale>1 1 1</scale>
        <link name='link'>
          <pose>0 0 0 0 -0 0</pose>
          <velocity>0 0 0 0 -0 0</velocity>
          <acceleration>0 0 0 0 -0 0</acceleration>
          <wrench>0 0 0 0 -0 0</wrench>
        </link>
      </model>
      <model name='ur'>
        <pose>0 -0 1e-06 -1e-06 -0 -0</pose>
        <scale>1 1 1</scale>
        <link name='base_link'>
          <pose>0 -0 1e-06 -1e-06 -0 -0</pose>
          <velocity>0 -2e-06 9.9e-05 0.000121 5.6e-05 3.3e-05</velocity>
          <acceleration>0.006669 -0.018877 0.198919 0.242782 0.112177 0.066818</acceleration>
          <wrench>0.013817 -0.039114 0.412159 0 -0 0</wrench>
        </link>
        <link name='forearm_link'>
          <pose>0.106303 0.096119 0.348771 -1.5708 1.36208 0.735134</pose>
          <velocity>0.005333 0.007389 -0.00641 0.029044 -0.032173 0.01329</velocity>
          <acceleration>1.93054 3.84743 -7.26106 -1.8773 -0.667259 -2.466</acceleration>
          <wrench>2.43248 4.84776 -9.14893 0 -0 0</wrench>
        </link>
        <link name='shoulder_link'>
          <pose>0 -0 0.151851 -1e-06 0 -2.40646</pose>
          <velocity>1.5e-05 -3.4e-05 9.9e-05 0.000178 0.000134 0.013328</velocity>
          <acceleration>0.023906 -0.054581 0.198483 0.299751 0.190399 0.794977</acceleration>
          <wrench>0.047811 -0.109163 0.396966 0 -0 0</wrench>
        </link>
        <link name='upper_arm_link'>
          <pose>0 -0 0.151851 1.5708 0.941666 -2.40646</pose>
          <velocity>1.1e-05 -2e-05 8e-05 -0.030353 0.033606 0.013325</velocity>
          <acceleration>1.50418 2.5723 -3.04579 2.92613 -1.25454 0.513753</acceleration>
          <wrench>5.1443 8.79726 -10.4166 0 -0 0</wrench>
        </link>
        <link name='wrist_1_link'>
          <pose>-0.014358 0.163696 0.557344 -1.5708 -0.000124 0.735136</pose>
          <velocity>-0.002283 -0.000264 -0.008336 -0.009986 0.010885 0.01326</velocity>
          <acceleration>-2.25706 -0.334727 -8.21603 0.284998 -0.71491 -1.36276</acceleration>
          <wrench>-1.80565 -0.267782 -6.57282 0 -0 0</wrench>
        </link>
        <link name='wrist_2_link'>
          <pose>-0.014366 0.163688 0.642694 8.7e-05 -8.9e-05 8.4e-05</pose>
          <velocity>-0.001361 0.000596 -0.008336 -0.01007 0.01081 -0.008027</velocity>
          <acceleration>-1.33 0.515675 -8.21585 -0.524325 -1.4417 1.43095</acceleration>
          <wrench>-1.064 0.41254 -6.57268 0 -0 0</wrench>
        </link>
        <link name='wrist_3_link'>
          <pose>-0.014374 0.255788 0.642702 -1.57071 0.001509 8.4e-05</pose>
          <velocity>-0.000624 0.000598 -0.009263 -0.010072 -5.6e-05 -0.008014</velocity>
          <acceleration>-0.755976 0.517756 -8.93323 2.6159 -0.000121 2.07121</acceleration>
          <wrench>-0.264591 0.181214 -3.12663 0 -0 0</wrench>
        </link>
      </model>
      <model name='wood_cube_10cm'>
        <pose>0.036705 0.422498 -0.001013 0 -0 0</pose>
        <scale>1 1 1</scale>
        <link name='link'>
          <pose>0.036705 0.422498 0.048987 0 -0 0</pose>
          <velocity>0 0 0 0 -0 0</velocity>
          <acceleration>0 -0 0 0 -0 0</acceleration>
          <wrench>0 -0 0 0 -0 0</wrench>
        </link>
      </model>
      <light name='sun'>
        <pose>0 0 10 0 -0 0</pose>
      </light>
    </state>
    <gui fullscreen='0'>
      <camera name='user_camera'>
        <pose>-2.70206 -0.134362 1.05108 -0 0.147643 -0.171805</pose>
        <view_controller>orbit</view_controller>
        <projection_type>perspective</projection_type>
      </camera>
    </gui>
  </world>
</sdf>
